Workbook

Sheet Tracker
A1: ICPC Prelims Prep Tracker • Sep 13 – Sep 30, 2026
A2: Naam mein kya rakha hai??
A3: Date | B3: Day | C3: Topic Focus | D3: Problem (CSES) | E3: Priority | F3: Asmitha | G3: Divya | H3: Archita
A4: Sep 13 | B4: Sunday | C4: Implementation & Simulation | D4: Weird Algorithm | E4: Core | F4: =FALSE() -> 0 | G4: =FALSE() -> 0 | H4: =FALSE() -> 0
D5: Missing Number | E5: Core | F5: =FALSE() -> 0 | G5: =FALSE() -> 0 | H5: =FALSE() -> 0
D6: Repetitions | E6: Core | F6: =FALSE() -> 0 | G6: =FALSE() -> 0 | H6: =FALSE() -> 0
D7: Increasing Array | E7: Core | F7: =FALSE() -> 0 | G7: =FALSE() -> 0 | H7: =FALSE() -> 0
D8: Permutations | E8: Core | F8: =FALSE() -> 0 | G8: =FALSE() -> 0 | H8: =FALSE() -> 0
A9: Sep 14 | B9: Monday | C9: Implementation & Math | D9: Number Spiral | E9: Core | F9: =FALSE() -> 0 | G9: =FALSE() -> 0 | H9: =FALSE() -> 0
D10: Two Sets | E10: Extra | F10: =FALSE() -> 0 | G10: =FALSE() -> 0 | H10: =FALSE() -> 0
A11: Sep 15 | B11: Tuesday | C11: Sorting & Searching Basics | D11: Distinct Numbers | E11: Core | F11: =FALSE() -> 0 | G11: =FALSE() -> 0 | H11: =FALSE() -> 0
D12: Apartments | E12: Core | F12: =FALSE() -> 0 | G12: =FALSE() -> 0 | H12: =FALSE() -> 0
A13: Sep 16 | B13: Wednesday | C13: Sorting & Two Pointers | D13: Ferris Wheel | E13: Core | F13: =FALSE() -> 0 | G13: =FALSE() -> 0 | H13: =FALSE() -> 0
D14: Concert Tickets | E14: Core | F14: =FALSE() -> 0 | G14: =FALSE() -> 0 | H14: =FALSE() -> 0
A15: Sep 17 | B15: Thursday | C15: Rest Day | D15: No questions — recharge
A16: Sep 18 | B16: Friday | C16: Greedy Sorting | D16: Movie Festival | E16: Core | F16: =FALSE() -> 0 | G16: =FALSE() -> 0 | H16: =FALSE() -> 0
D17: Maximum Subarray Sum | E17: Core | F17: =FALSE() -> 0 | G17: =FALSE() -> 0 | H17: =FALSE() -> 0
A18: Sep 19 | B18: Saturday | C18: Sorting & Searching Advanced | D18: Stick Lengths | E18: Core | F18: =FALSE() -> 0 | G18: =FALSE() -> 0 | H18: =FALSE() -> 0
D19: Playlist | E19: Core | F19: =FALSE() -> 0 | G19: =FALSE() -> 0 | H19: =FALSE() -> 0
D20: Factory Machines | E20: Extra | F20: =FALSE() -> 0 | G20: =FALSE() -> 0 | H20: =FALSE() -> 0
D21: Tasks and Deadlines | E21: Extra | F21: =FALSE() -> 0 | G21: =FALSE() -> 0 | H21: =FALSE() -> 0
A22: Sep 20 | B22: Sunday | C22: Elementary Number Theory | D22: Exponentiation | E22: Core | F22: =FALSE() -> 0 | G22: =FALSE() -> 0 | H22: =FALSE() -> 0
D23: Exponentiation II | E23: Core | F23: =FALSE() -> 0 | G23: =FALSE() -> 0 | H23: =FALSE() -> 0
D24: Counting Divisors | E24: Core | F24: =FALSE() -> 0 | G24: =FALSE() -> 0 | H24: =FALSE() -> 0
D25: Common Divisors | E25: Core | F25: =FALSE() -> 0 | G25: =FALSE() -> 0 | H25: =FALSE() -> 0
D26: Sum of Divisors | E26: Core | F26: =FALSE() -> 0 | G26: =FALSE() -> 0 | H26: =FALSE() -> 0
A27: Sep 21 | B27: Monday | C27: Number Theory & Combinatorics | D27: Prime Multiples | E27: Core | F27: =FALSE() -> 0 | G27: =FALSE() -> 0 | H27: =FALSE() -> 0
D28: Divisor Analysis | E28: Extra | F28: =FALSE() -> 0 | G28: =FALSE() -> 0 | H28: =FALSE() -> 0
A29: Sep 22 | B29: Tuesday | C29: Combinatorics & Intro Graphs | D29: Creating Strings II | E29: Extra | F29: =FALSE() -> 0 | G29: =FALSE() -> 0 | H29: =FALSE() -> 0
D30: Counting Rooms | E30: Core | F30: =FALSE() -> 0 | G30: =FALSE() -> 0 | H30: =FALSE() -> 0
A31: Sep 23 | B31: Wednesday | C31: Graph Traversals (Grid) | D31: Labyrinth | E31: Core | F31: =FALSE() -> 0 | G31: =FALSE() -> 0 | H31: =FALSE() -> 0
D32: Building Roads | E32: Core | F32: =FALSE() -> 0 | G32: =FALSE() -> 0 | H32: =FALSE() -> 0
A33: Sep 24 | B33: Thursday | C33: Rest Day | D33: No questions — recharge
A34: Sep 25 | B34: Friday | C34: Graph Paths | D34: Message Route | E34: Core | F34: =FALSE() -> 0 | G34: =FALSE() -> 0 | H34: =FALSE() -> 0
D35: Building Teams | E35: Core | F35: =FALSE() -> 0 | G35: =FALSE() -> 0 | H35: =FALSE() -> 0
A36: Sep 26 | B36: Saturday | C36: Shortest Paths & Topo Sort | D36: Shortest Routes I (Dijkstra) | E36: Core | F36: =FALSE() -> 0 | G36: =FALSE() -> 0 | H36: =FALSE() -> 0
D37: Course Schedule | E37: Core | F37: =FALSE() -> 0 | G37: =FALSE() -> 0 | H37: =FALSE() -> 0
D38: Shortest Routes II | E38: Extra | F38: =FALSE() -> 0 | G38: =FALSE() -> 0 | H38: =FALSE() -> 0
D39: Round Trip | E39: Extra | F39: =FALSE() -> 0 | G39: =FALSE() -> 0 | H39: =FALSE() -> 0
A40: Sep 27 | B40: Sunday | C40: DP Foundations (1D) | D40: Dice Combinations | E40: Core | F40: =FALSE() -> 0 | G40: =FALSE() -> 0 | H40: =FALSE() -> 0
...

Sheet Summary
A1: Team Progress Summary
A3: Team Member | B3: Done | C3: Pending | D3: % Complete
A4: Asmitha | B4: =COUNTIF(Tracker!F4:F50,TRUE()) -> 0 | C4: =COUNTIF(Tracker!F4:F50,FALSE()) -> 45 | D4: =IFERROR(B4/(COUNTA(Tracker!D4:D50)-COUNTIF(Tracker!E4:E50,"")),0) -> 0
A5: Divya | B5: =COUNTIF(Tracker!G4:G50,TRUE()) -> 0 | C5: =COUNTIF(Tracker!G4:G50,FALSE()) -> 45 | D5: =IFERROR(B5/(COUNTA(Tracker!D4:D50)-COUNTIF(Tracker!E4:E50,"")),0) -> 0
A6: Archita | B6: =COUNTIF(Tracker!H4:H50,TRUE()) -> 0 | C6: =COUNTIF(Tracker!H4:H50,FALSE()) -> 45 | D6: =IFERROR(B6/(COUNTA(Tracker!D4:D50)-COUNTIF(Tracker!E4:E50,"")),0) -> 0
A9: Total active problems (rest days excluded): | B9: =COUNTA(Tracker!D4:D50)-COUNTIF(Tracker!E4:E50,"") -> 45
